Workbook

Sheet Provstidata
A1: Stift | B1: Provsti | C1: Indbyggertal | D1: Folkekirkemedlemmer | E1: Ikke-medlemmer | F1: Medlemsprocent | G1: Befolkning 2040 | H1: Befolkningsændring til 2040 | I1: Befolkningsændring til 2040 % | J1: Lokal ligning t.kr. | K1: Maks. stiftsbidrag 1 % (t.kr.) | L1: Menighedsråd | M1: Pastorater | N1: Sogne | O1: Kirker | P1: Præster inkl. LOFI | Q1: Præsteårsværk inkl. LOFI | R1: Sognepræster | S1: Overenskomstansatte sognepræster | T1: Præster i alt | U1: Datakilde primær | V1: Datakilde supplerende
A2: Fyens Stift | B2: Assens Provsti | C2: 40053 | D2: 32527 | E2: 7526 | F2: 0.81209897 | G2: 38708 | H2: -1345 | J2: 59205.43 | K2: 592.0543 | L2: 22 | M2: 16 | N2: 29 | O2: 31 | P2: 18 | Q2: 18 | R2: 20 | S2: 0 | T2: 20 | U2: Tabel vedr. stifter og provstier slut torsdag | V2: provsti.dk-data fra tidligere app-datasæt
A3: Fyens Stift | B3: Bogense Provsti | C3: 29392 | D3: 24016 | E3: 5376 | F3: 0.81709309 | G3: 28490 | H3: -902 | J3: 45762.202 | K3: 457.62202 | L3: 18 | M3: 11 | N3: 27 | O3: 30 | P3: 14 | Q3: 14 | R3: 15 | S3: 4 | T3: 19 | U3: Tabel vedr. stifter og provstier slut torsdag | V3: provsti.dk-data fra tidligere app-datasæt
A4: Fyens Stift | B4: Fåborg Provsti | C4: 21957 | D4: 17515 | E4: 4442 | F4: 0.7976955 | G4: 22412 | H4: 455 | J4: 76840.259 | K4: 768.40259 | L4: 14 | M4: 9 | N4: 18 | O4: 20 | P4: 10 | Q4: 10 | R4: 16 | S4: 0 | T4: 16 | U4: Tabel vedr. stifter og provstier slut torsdag | V4: provsti.dk-data fra tidligere app-datasæt
A5: Fyens Stift | B5: Hjallese Provsti | C5: 104714 | D5: 79163 | E5: 25551 | F5: 0.75599251 | K5: 0 | L5: 20 | M5: 17 | N5: 25 | O5: 27 | P5: 36 | Q5: 36 | R5: 32 | S5: 12 | T5: 44 | U5: Tabel vedr. stifter og provstier slut torsdag | V5: provsti.dk-data fra tidligere app-datasæt
A6: Fyens Stift | B6: Kerteminde-Nyborg Provsti | C6: 56771 | D6: 44413 | E6: 12358 | F6: 0.78231844 | G6: 56514 | H6: -257 | J6: 81248.872 | K6: 812.48872 | L6: 18 | M6: 18 | N6: 30 | O6: 39 | P6: 21 | Q6: 21 | R6: 24 | S6: 3 | T6: 27 | U6: Tabel vedr. stifter og provstier slut torsdag | V6: provsti.dk-data fra tidligere app-datasæt
A7: Fyens Stift | B7: Langeland-Ærø Provsti | C7: 17556 | D7: 13767 | E7: 3789 | F7: 0.78417635 | G7: 16302 | H7: -1254 | J7: 28842.8 | K7: 288.428 | L7: 9 | M7: 7 | N7: 24 | O7: 30 | P7: 11 | Q7: 11 | R7: 12 | S7: 0 | T7: 12 | U7: Tabel vedr. stifter og provstier slut torsdag | V7: provsti.dk-data fra tidligere app-datasæt
A8: Fyens Stift | B8: Middelfart Provsti | C8: 40606 | D8: 33146 | E8: 7460 | F8: 0.81628331 | G8: 42741 | H8: 2135 | J8: 58156.085 | K8: 581.56085 | L8: 13 | M8: 10 | N8: 21 | O8: 24 | P8: 13 | Q8: 13 | R8: 14 | S8: 2 | T8: 16 | U8: Tabel vedr. stifter og provstier slut torsdag | V8: provsti.dk-data fra tidligere app-datasæt
A9: Fyens Stift | B9: Midtfyn Provsti | C9: 30316 | D9: 24467 | E9: 5849 | F9: 0.80706558 | K9: 0 | L9: 13 | M9: 11 | N9: 18 | O9: 23 | P9: 8 | Q9: 8 | R9: 18 | S9: 0 | T9: 18 | U9: Tabel vedr. stifter og provstier slut torsdag | V9: provsti.dk-data fra tidligere app-datasæt
A10: Fyens Stift | B10: Odense Sankt Knuds Provsti | C10: 108717 | D10: 70051 | E10: 38666 | F10: 0.64434265 | G10: 117149 | H10: 8432 | J10: 174147.86 | K10: 1741.4786 | L10: 11 | M10: 11 | N10: 11 | O10: 17 | P10: 26 | Q10: 26 | R10: 22 | S10: 8 | T10: 30 | U10: Tabel vedr. stifter og provstier slut torsdag | V10: provsti.dk-data fra tidligere app-datasæt
A11: Fyens Stift | B11: Svendborg Provsti | C11: 60064 | D11: 45484 | E11: 14580 | F11: 0.75725892 | G11: 62791 | H11: 2727 | J11: 84114.012 | K11: 841.14012 | L11: 19 | M11: 18 | N11: 28 | O11: 34 | P11: 20 | Q11: 20 | R11: 32 | S11: 2 | T11: 34 | U11: Tabel vedr. stifter og provstier slut torsdag | V11: provsti.dk-data fra tidligere app-datasæt
A12: Haderslev Stift | B12: Fredericia Provsti | C12: 52920 | D12: 39397 | E12: 13523 | F12: 0.74446334 | G12: 54541 | H12: 1621 | J12: 67414.748 | K12: 674.14748 | L12: 10 | M12: 10 | N12: 11 | O12: 14 | P12: 20 | Q12: 20 | R12: 15 | S12: 6 | T12: 21 | U12: Tabel vedr. stifter og provstier slut torsdag | V12: provsti.dk-data fra tidligere app-datasæt
A13: Haderslev Stift | B13: Haderslev Domprovsti | C13: 55128 | D13: 42941 | E13: 12187 | F13: 0.77893267 | G13: 52775 | H13: -2353 | J13: 77002.24 | K13: 770.0224 | L13: 25 | M13: 18 | N13: 27 | O13: 32 | P13: 27 | Q13: 27 | R13: 28 | S13: 4 | T13: 32 | U13: Tabel vedr. stifter og provstier slut torsdag | V13: provsti.dk-data fra tidligere app-datasæt
A14: Haderslev Stift | B14: Hedensted Provsti | C14: 48584 | D14: 38907 | E14: 9677 | F14: 0.8008192 | G14: 52440 | H14: 3856 | J14: 70743.248 | K14: 707.43248 | L14: 20 | M14: 16 | N14: 33 | O14: 37 | P14: 22 | Q14: 22 | R14: 18 | S14: 4 | T14: 22 | U14: Tabel vedr. stifter og provstier slut torsdag | V14: provsti.dk-data fra tidligere app-datasæt
A15: Haderslev Stift | B15: Kolding Provsti | C15: 96295 | D15: 71735 | E15: 24560 | F15: 0.74495041 | G15: 99337 | H15: 3042 | J15: 127013.16 | K15: 1270.1316 | L15: 24 | M15: 22 | N15: 30 | O15: 39 | P15: 34 | Q15: 34 | R15: 32 | S15: 12 | T15: 44 | U15: Tabel vedr. stifter og provstier slut torsdag | V15: provsti.dk-data fra tidligere app-datasæt
A16: Haderslev Stift | B16: Sønderborg Provsti | C16: 74007 | D16: 54438 | E16: 19569 | F16: 0.73557907 | G16: 70785 | H16: -3222 | J16: 96872.301 | K16: 968.72301 | L16: 23 | M16: 20 | N16: 25 | O16: 36 | P16: 27 | Q16: 27 | R16: 27 | S16: 3 | T16: 30 | U16: Tabel vedr. stifter og provstier slut torsdag | V16: provsti.dk-data fra tidligere app-datasæt
A17: Haderslev Stift | B17: Vejle Provsti | C17: 105803 | D17: 76427 | E17: 29376 | F17: 0.72235192 | G17: 115251 | H17: 9448 | J17: 157938.06 | K17: 1579.3806 | L17: 24 | M17: 23 | N17: 27 | O17: 38 | P17: 40 | Q17: 40 | R17: 29 | S17: 13 | T17: 42 | U17: Tabel vedr. stifter og provstier slut torsdag | V17: provsti.dk-data fra tidligere app-datasæt
A18: Haderslev Stift | B18: Aabenraa Provsti | C18: 58295 | D18: 42800 | E18: 15495 | F18: 0.73419676 | G18: 55521 | H18: -2774 | J18: 76710.98 | K18: 767.1098 | L18: 19 | M18: 16 | N18: 20 | O18: 26 | P18: 24 | Q18: 24 | R18: 23 | S18: 4 | T18: 27 | U18: Tabel vedr. stifter og provstier slut torsdag | V18: provsti.dk-data fra tidligere app-datasæt
A19: Helsingør Stift | B19: Ballerup-Furesø Provsti | C19: 96886 | D19: 57614 | E19: 39272 | F19: 0.59465764 | G19: 107269 | H19: 10383 | J19: 94940.907 | K19: 949.40907 | L19: 7 | M19: 6 | N19: 7 | O19: 13 | P19: 25 | Q19: 25 | R19: 20 | S19: 7 | T19: 27 | U19: Tabel vedr. stifter og provstier slut torsdag | V19: provsti.dk-data fra tidligere app-datasæt
A20: Helsingør Stift | B20: Fredensborg Provsti | C20: 67449 | D20: 44535 | E20: 22914 | F20: 0.66027665 | G20: 67792 | H20: 343 | J20: 68792.458 | K20: 687.92458 | L20: 6 | M20: 6 | N20: 6 | O20: 13 | P20: 17 | Q20: 17 | R20: 17 | S20: 5 | T20: 22 | U20: Tabel vedr. stifter og provstier slut torsdag | V20: provsti.dk-data fra tidligere app-datasæt
A21: Helsingør Stift | B21: Frederikssund Provsti | C21: 94104 | D21: 68391 | E21: 25713 | F21: 0.72675976 | G21: 99395 | H21: 5291 | J21: 121566.87 | K21: 1215.6687 | L21: 17 | M21: 15 | N21: 25 | O21: 28 | P21: 32 | Q21: 32 | R21: 28 | S21: 7 | T21: 35 | U21: Tabel vedr. stifter og provstier slut torsdag | V21: provsti.dk-data fra tidligere app-datasæt
A22: Helsingør Stift | B22: Frederiksværk Provsti | C22: 73710 | D22: 53698 | E22: 20012 | F22: 0.7285036 | G22: 74147 | H22: 437 | J22: 90257.527 | K22: 902.57527 | L22: 16 | M22: 13 | N22: 18 | O22: 25 | P22: 23 | Q22: 23 | R22: 23 | S22: 4 | T22: 27 | U22: Tabel vedr. stifter og provstier slut torsdag | V22: provsti.dk-data fra tidligere app-datasæt
A23: Helsingør Stift | B23: Gentofte Provsti | C23: 75086 | D23: 48605 | E23: 26481 | F23: 0.6473244 | G23: 71620 | H23: -3466 | I23: -0.046275033 | J23: 62914.377 | K23: 629.14377 | L23: 9 | M23: 9 | N23: 9 | O23: 14 | P23: 19 | Q23: 19 | R23: 21 | S23: 3 | T23: 24 | U23: Tabel vedr. stifter og provstier slut torsdag | V23: provsti.dk-data fra tidligere app-datasæt
A24: Helsingør Stift | B24: Gladsaxe-Herlev Provsti | C24: 103096 | D24: 55870 | E24: 47226 | F24: 0.54192209 | G24: 107077 | H24: 3981 | I24: 0.038890626 | J24: 94535.17 | K24: 945.3517 | L24: 10 | M24: 10 | N24: 11 | O24: 14 | P24: 28 | Q24: 28 | R24: 29 | S24: 4 | T24: 33 | U24: Tabel vedr. stifter og provstier slut torsdag | V24: provsti.dk-data fra tidligere app-datasæt
A25: Helsingør Stift | B25: Glostrup Provsti | C25: 114960 | D25: 54408 | E25: 60552 | F25: 0.47327766 | G25: 125095 | H25: 10135 | I25: 0.08960621 | J25: 87883.824 | K25: 878.83824 | L25: 9 | M25: 9 | N25: 9 | O25: 17 | P25: 29 | Q25: 29 | R25: 29 | S25: 4 | T25: 33 | U25: Tabel vedr. stifter og provstier slut torsdag | V25: provsti.dk-data fra tidligere app-datasæt
A26: Helsingør Stift | B26: Helsingør Domprovsti | C26: 64392 | D26: 43290 | E26: 21102 | F26: 0.67228848 | G26: 65520 | H26: 1128 | I26: 0.017581047 | J26: 55124.838 | K26: 551.24838 | L26: 10 | M26: 9 | N26: 10 | O26: 12 | P26: 21 | Q26: 21 | R26: 17 | S26: 6 | T26: 23 | U26: Tabel vedr. stifter og provstier slut torsdag | V26: provsti.dk-data fra tidligere app-datasæt
A27: Helsingør Stift | B27: Hillerød Provsti | C27: 82244 | D27: 56842 | E27: 25402 | F27: 0.69113856 | G27: 87112 | H27: 4868 | J27: 79963.177 | K27: 799.63177 | L27: 15 | M27: 14 | N27: 20 | O27: 25 | P27: 27 | Q27: 27 | R27: 21 | S27: 10 | T27: 31 | U27: Tabel vedr. stifter og provstier slut torsdag | V27: provsti.dk-data fra tidligere app-datasæt
A28: Helsingør Stift | B28: Høje Taastrup Provsti | C28: 85576 | D28: 37529 | E28: 48047 | F28: 0.43854585 | G28: 95946 | H28: 10370 | J28: 63559.28 | K28: 635.5928 | L28: 9 | M28: 7 | N28: 9 | O28: 11 | P28: 18 | Q28: 18 | R28: 16 | S28: 4 | T28: 20 | U28: Tabel vedr. stifter og provstier slut torsdag | V28: provsti.dk-data fra tidligere app-datasæt
A29: Helsingør Stift | B29: Kongens Lyngby Provsti | C29: 58922 | D29: 36601 | E29: 22321 | F29: 0.62117715 | G29: 59593 | H29: 671 | J29: 63228.431 | K29: 632.28431 | L29: 6 | M29: 6 | N29: 6 | O29: 10 | P29: 18 | Q29: 18 | R29: 14 | S29: 7 | T29: 21 | U29: Tabel vedr. stifter og provstier slut torsdag | V29: provsti.dk-data fra tidligere app-datasæt
A30: Helsingør Stift | B30: Rudersdal Provsti | C30: 58077 | D30: 39123 | E30: 18954 | F30: 0.67364017 | G30: 56728 | H30: -1349 | J30: 66611.508 | K30: 666.11508 | L30: 8 | M30: 8 | N30: 8 | O30: 11 | P30: 20 | Q30: 20 | R30: 15 | S30: 5 | T30: 20 | U30: Tabel vedr. stifter og provstier slut torsdag | V30: provsti.dk-data fra tidligere app-datasæt
A31: Helsingør Stift | B31: Rødovre-Hvidovre Provsti | C31: 99291 | D31: 56326 | E31: 42965 | F31: 0.56728203 | G31: 104534 | H31: 5243 | J31: 80698.25 | K31: 806.9825 | L31: 8 | M31: 8 | N31: 8 | O31: 14 | P31: 25 | Q31: 25 | R31: 26 | S31: 1 | T31: 27 | U31: Tabel vedr. stifter og provstier slut torsdag | V31: provsti.dk-data fra tidligere app-datasæt
A32: Københavns Stift | B32: Amagerbro Provsti | C32: 170117 | D32: 82209 | E32: 87908 | F32: 0.48324976 | K32: 0 | L32: 12 | M32: 10 | N32: 12 | O32: 16 | P32: 33 | Q32: 33 | R32: 31 | S32: 5 | T32: 36 | U32: Tabel vedr. stifter og provstier slut torsdag | V32: provsti.dk-data fra tidligere app-datasæt
A33: Københavns Stift | B33: Amagerland Provsti | C33: 58698 | D33: 40442 | E33: 18256 | F33: 0.68898429 | G33: 58895 | H33: 197 | I33: 0.0033579355 | J33: 48688.61 | K33: 486.8861 | L33: 6 | M33: 6 | N33: 6 | O33: 9 | P33: 18 | Q33: 18 | R33: 15 | S33: 4 | T33: 19 | U33: Tabel vedr. stifter og provstier slut torsdag | V33: provsti.dk-data fra tidligere app-datasæt
A34: Københavns Stift | B34: Bispebjerg-Brønshøj Provsti | C34: 96440 | D34: 40597 | E34: 55843 | F34: 0.42095603 | K34: 0 | L34: 10 | M34: 9 | N34: 10 | O34: 14 | P34: 25 | Q34: 25 | R34: 21 | S34: 8 | T34: 29 | U34: Tabel vedr. stifter og provstier slut torsdag | V34: provsti.dk-data fra tidligere app-datasæt
A35: Københavns Stift | B35: Bornholms Provsti | C35: 38703 | D35: 29081 | E35: 9622 | F35: 0.75138878 | G35: 35560 | H35: -3143 | I35: -0.081007242 | J35: 49111.137 | K35: 491.11137 | L35: 18 | M35: 14 | N35: 22 | O35: 29 | P35: 18 | Q35: 18 | R35: 20 | S35: 1 | T35: 21 | U35: Tabel vedr. stifter og provstier slut torsdag | V35: provsti.dk-data fra tidligere app-datasæt
A36: Københavns Stift | B36: Frederiksberg Provsti | C36: 106433 | D36: 61301 | E36: 45132 | F36: 0.57595858 | G36: 102632 | H36: -3801 | I36: -0.035889301 | J36: 70094.214 | K36: 700.94214 | L36: 9 | M36: 9 | N36: 9 | O36: 18 | P36: 28 | Q36: 28 | R36: 28 | S36: 1 | T36: 29 | U36: Tabel vedr. stifter og provstier slut torsdag | V36: provsti.dk-data fra tidligere app-datasæt
A37: Københavns Stift | B37: Holmens og Østerbro Provsti | C37: 112850 | D37: 61354 | E37: 51496 | F37: 0.54367745 | K37: 0 | L37: 14 | M37: 13 | N37: 14 | O37: 20 | P37: 28 | Q37: 28 | R37: 26 | S37: 3 | T37: 29 | U37: Tabel vedr. stifter og provstier slut torsdag | V37: provsti.dk-data fra tidligere app-datasæt
A38: Københavns Stift | B38: Nørrebro Provsti | C38: 76456 | D38: 35310 | E38: 41146 | F38: 0.46183426 | G38: 105725 | H38: 29269 | I38: 0.043510772 | J38: 591550.65 | K38: 5915.5065 | L38: 6 | M38: 5 | N38: 6 | O38: 12 | P38: 19 | Q38: 19 | R38: 17 | S38: 1 | T38: 18 | U38: Tabel vedr. stifter og provstier slut torsdag | V38: provsti.dk-data fra tidligere app-datasæt
A39: Københavns Stift | B39: Valby-Vanløse Provsti | C39: 108748 | D39: 56847 | E39: 51901 | F39: 0.52274065 | K39: 0 | L39: 9 | M39: 9 | N39: 9 | O39: 12 | P39: 24 | Q39: 24 | R39: 23 | S39: 2 | T39: 25 | U39: Tabel vedr. stifter og provstier slut torsdag | V39: provsti.dk-data fra tidligere app-datasæt
A40: Københavns Stift | B40: Vor Frue-Vesterbro Provsti | C40: 108827 | D40: 51772 | E40: 57055 | F40: 0.47572753 | K40: 0 | L40: 7 | M40: 7 | N40: 7 | O40: 20 | P40: 32 | Q40: 32 | R40: 23 | S40: 7 | T40: 30 | U40: Tabel vedr. stifter og provstier slut torsdag | V40: provsti.dk-data fra tidligere app-datasæt
...

Sheet Stiftssummer
A1: Stift | B1: Provstier | C1: Indbyggertal | D1: Folkekirkemedlemmer | E1: Ikke-medlemmer | F1: Medlemsprocent | G1: Befolkning 2040 | H1: Befolkningsændring | I1: Lokal ligning t.kr. | J1: Maks. stiftsbidrag 1 % (t.kr.) | K1: Menighedsråd | L1: Pastorater | M1: Sogne | N1: Kirker | O1: Præster inkl. LOFI | P1: Sognepræster | Q1: Overenskomstansatte sognepræster | R1: Præster i alt
A2: Fyens Stift | B2: =COUNTIF(Provstidata!$A:$A,$A2) | C2: =SUMIF(Provstidata!$A:$A,$A2,Provstidata!$C:$C) | D2: =SUMIF(Provstidata!$A:$A,$A2,Provstidata!$D:$D) | E2: =SUMIF(Provstidata!$A:$A,$A2,Provstidata!$E:$E) | F2: =IF(C2=0,"",D2/C2) | G2: =SUMIF(Provstidata!$A:$A,$A2,Provstidata!$G:$G) | H2: =SUMIF(Provstidata!$A:$A,$A2,Provstidata!$H:$H) | I2: =SUMIF(Provstidata!$A:$A,$A2,Provstidata!$J:$J) | J2: =SUMIF(Provstidata!$A:$A,$A2,Provstidata!$K:$K) | K2: =SUMIF(Provstidata!$A:$A,$A2,Provstidata!$L:$L) | L2: =SUMIF(Provstidata!$A:$A,$A2,Provstidata!$M:$M) | M2: =SUMIF(Provstidata!$A:$A,$A2,Provstidata!$N:$N) | N2: =SUMIF(Provstidata!$A:$A,$A2,Provstidata!$O:$O) | O2: =SUMIF(Provstidata!$A:$A,$A2,Provstidata!$P:$P) | P2: =SUMIF(Provstidata!$A:$A,$A2,Provstidata!$R:$R) | Q2: =SUMIF(Provstidata!$A:$A,$A2,Provstidata!$S:$S) | R2: =SUMIF(Provstidata!$A:$A,$A2,Provstidata!$T:$T)
A3: Haderslev Stift | B3: =COUNTIF(Provstidata!$A:$A,$A3) | C3: =SUMIF(Provstidata!$A:$A,$A3,Provstidata!$C:$C) | D3: =SUMIF(Provstidata!$A:$A,$A3,Provstidata!$D:$D) | E3: =SUMIF(Provstidata!$A:$A,$A3,Provstidata!$E:$E) | F3: =IF(C3=0,"",D3/C3) | G3: =SUMIF(Provstidata!$A:$A,$A3,Provstidata!$G:$G) | H3: =SUMIF(Provstidata!$A:$A,$A3,Provstidata!$H:$H) | I3: =SUMIF(Provstidata!$A:$A,$A3,Provstidata!$J:$J) | J3: =SUMIF(Provstidata!$A:$A,$A3,Provstidata!$K:$K) | K3: =SUMIF(Provstidata!$A:$A,$A3,Provstidata!$L:$L) | L3: =SUMIF(Provstidata!$A:$A,$A3,Provstidata!$M:$M) | M3: =SUMIF(Provstidata!$A:$A,$A3,Provstidata!$N:$N) | N3: =SUMIF(Provstidata!$A:$A,$A3,Provstidata!$O:$O) | O3: =SUMIF(Provstidata!$A:$A,$A3,Provstidata!$P:$P) | P3: =SUMIF(Provstidata!$A:$A,$A3,Provstidata!$R:$R) | Q3: =SUMIF(Provstidata!$A:$A,$A3,Provstidata!$S:$S) | R3: =SUMIF(Provstidata!$A:$A,$A3,Provstidata!$T:$T)
A4: Helsingør Stift | B4: =COUNTIF(Provstidata!$A:$A,$A4) | C4: =SUMIF(Provstidata!$A:$A,$A4,Provstidata!$C:$C) | D4: =SUMIF(Provstidata!$A:$A,$A4,Provstidata!$D:$D) | E4: =SUMIF(Provstidata!$A:$A,$A4,Provstidata!$E:$E) | F4: =IF(C4=0,"",D4/C4) | G4: =SUMIF(Provstidata!$A:$A,$A4,Provstidata!$G:$G) | H4: =SUMIF(Provstidata!$A:$A,$A4,Provstidata!$H:$H) | I4: =SUMIF(Provstidata!$A:$A,$A4,Provstidata!$J:$J) | J4: =SUMIF(Provstidata!$A:$A,$A4,Provstidata!$K:$K) | K4: =SUMIF(Provstidata!$A:$A,$A4,Provstidata!$L:$L) | L4: =SUMIF(Provstidata!$A:$A,$A4,Provstidata!$M:$M) | M4: =SUMIF(Provstidata!$A:$A,$A4,Provstidata!$N:$N) | N4: =SUMIF(Provstidata!$A:$A,$A4,Provstidata!$O:$O) | O4: =SUMIF(Provstidata!$A:$A,$A4,Provstidata!$P:$P) | P4: =SUMIF(Provstidata!$A:$A,$A4,Provstidata!$R:$R) | Q4: =SUMIF(Provstidata!$A:$A,$A4,Provstidata!$S:$S) | R4: =SUMIF(Provstidata!$A:$A,$A4,Provstidata!$T:$T)
A5: Københavns Stift | B5: =COUNTIF(Provstidata!$A:$A,$A5) | C5: =SUMIF(Provstidata!$A:$A,$A5,Provstidata!$C:$C) | D5: =SUMIF(Provstidata!$A:$A,$A5,Provstidata!$D:$D) | E5: =SUMIF(Provstidata!$A:$A,$A5,Provstidata!$E:$E) | F5: =IF(C5=0,"",D5/C5) | G5: =SUMIF(Provstidata!$A:$A,$A5,Provstidata!$G:$G) | H5: =SUMIF(Provstidata!$A:$A,$A5,Provstidata!$H:$H) | I5: =SUMIF(Provstidata!$A:$A,$A5,Provstidata!$J:$J) | J5: =SUMIF(Provstidata!$A:$A,$A5,Provstidata!$K:$K) | K5: =SUMIF(Provstidata!$A:$A,$A5,Provstidata!$L:$L) | L5: =SUMIF(Provstidata!$A:$A,$A5,Provstidata!$M:$M) | M5: =SUMIF(Provstidata!$A:$A,$A5,Provstidata!$N:$N) | N5: =SUMIF(Provstidata!$A:$A,$A5,Provstidata!$O:$O) | O5: =SUMIF(Provstidata!$A:$A,$A5,Provstidata!$P:$P) | P5: =SUMIF(Provstidata!$A:$A,$A5,Provstidata!$R:$R) | Q5: =SUMIF(Provstidata!$A:$A,$A5,Provstidata!$S:$S) | R5: =SUMIF(Provstidata!$A:$A,$A5,Provstidata!$T:$T)
A6: Lolland-Falsters Stift | B6: =COUNTIF(Provstidata!$A:$A,$A6) | C6: =SUMIF(Provstidata!$A:$A,$A6,Provstidata!$C:$C) | D6: =SUMIF(Provstidata!$A:$A,$A6,Provstidata!$D:$D) | E6: =SUMIF(Provstidata!$A:$A,$A6,Provstidata!$E:$E) | F6: =IF(C6=0,"",D6/C6) | G6: =SUMIF(Provstidata!$A:$A,$A6,Provstidata!$G:$G) | H6: =SUMIF(Provstidata!$A:$A,$A6,Provstidata!$H:$H) | I6: =SUMIF(Provstidata!$A:$A,$A6,Provstidata!$J:$J) | J6: =SUMIF(Provstidata!$A:$A,$A6,Provstidata!$K:$K) | K6: =SUMIF(Provstidata!$A:$A,$A6,Provstidata!$L:$L) | L6: =SUMIF(Provstidata!$A:$A,$A6,Provstidata!$M:$M) | M6: =SUMIF(Provstidata!$A:$A,$A6,Provstidata!$N:$N) | N6: =SUMIF(Provstidata!$A:$A,$A6,Provstidata!$O:$O) | O6: =SUMIF(Provstidata!$A:$A,$A6,Provstidata!$P:$P) | P6: =SUMIF(Provstidata!$A:$A,$A6,Provstidata!$R:$R) | Q6: =SUMIF(Provstidata!$A:$A,$A6,Provstidata!$S:$S) | R6: =SUMIF(Provstidata!$A:$A,$A6,Provstidata!$T:$T)
A7: Ribe Stift | B7: =COUNTIF(Provstidata!$A:$A,$A7) | C7: =SUMIF(Provstidata!$A:$A,$A7,Provstidata!$C:$C) | D7: =SUMIF(Provstidata!$A:$A,$A7,Provstidata!$D:$D) | E7: =SUMIF(Provstidata!$A:$A,$A7,Provstidata!$E:$E) | F7: =IF(C7=0,"",D7/C7) | G7: =SUMIF(Provstidata!$A:$A,$A7,Provstidata!$G:$G) | H7: =SUMIF(Provstidata!$A:$A,$A7,Provstidata!$H:$H) | I7: =SUMIF(Provstidata!$A:$A,$A7,Provstidata!$J:$J) | J7: =SUMIF(Provstidata!$A:$A,$A7,Provstidata!$K:$K) | K7: =SUMIF(Provstidata!$A:$A,$A7,Provstidata!$L:$L) | L7: =SUMIF(Provstidata!$A:$A,$A7,Provstidata!$M:$M) | M7: =SUMIF(Provstidata!$A:$A,$A7,Provstidata!$N:$N) | N7: =SUMIF(Provstidata!$A:$A,$A7,Provstidata!$O:$O) | O7: =SUMIF(Provstidata!$A:$A,$A7,Provstidata!$P:$P) | P7: =SUMIF(Provstidata!$A:$A,$A7,Provstidata!$R:$R) | Q7: =SUMIF(Provstidata!$A:$A,$A7,Provstidata!$S:$S) | R7: =SUMIF(Provstidata!$A:$A,$A7,Provstidata!$T:$T)
A8: Roskilde Stift | B8: =COUNTIF(Provstidata!$A:$A,$A8) | C8: =SUMIF(Provstidata!$A:$A,$A8,Provstidata!$C:$C) | D8: =SUMIF(Provstidata!$A:$A,$A8,Provstidata!$D:$D) | E8: =SUMIF(Provstidata!$A:$A,$A8,Provstidata!$E:$E) | F8: =IF(C8=0,"",D8/C8) | G8: =SUMIF(Provstidata!$A:$A,$A8,Provstidata!$G:$G) | H8: =SUMIF(Provstidata!$A:$A,$A8,Provstidata!$H:$H) | I8: =SUMIF(Provstidata!$A:$A,$A8,Provstidata!$J:$J) | J8: =SUMIF(Provstidata!$A:$A,$A8,Provstidata!$K:$K) | K8: =SUMIF(Provstidata!$A:$A,$A8,Provstidata!$L:$L) | L8: =SUMIF(Provstidata!$A:$A,$A8,Provstidata!$M:$M) | M8: =SUMIF(Provstidata!$A:$A,$A8,Provstidata!$N:$N) | N8: =SUMIF(Provstidata!$A:$A,$A8,Provstidata!$O:$O) | O8: =SUMIF(Provstidata!$A:$A,$A8,Provstidata!$P:$P) | P8: =SUMIF(Provstidata!$A:$A,$A8,Provstidata!$R:$R) | Q8: =SUMIF(Provstidata!$A:$A,$A8,Provstidata!$S:$S) | R8: =SUMIF(Provstidata!$A:$A,$A8,Provstidata!$T:$T)
A9: Viborg Stift | B9: =COUNTIF(Provstidata!$A:$A,$A9) | C9: =SUMIF(Provstidata!$A:$A,$A9,Provstidata!$C:$C) | D9: =SUMIF(Provstidata!$A:$A,$A9,Provstidata!$D:$D) | E9: =SUMIF(Provstidata!$A:$A,$A9,Provstidata!$E:$E) | F9: =IF(C9=0,"",D9/C9) | G9: =SUMIF(Provstidata!$A:$A,$A9,Provstidata!$G:$G) | H9: =SUMIF(Provstidata!$A:$A,$A9,Provstidata!$H:$H) | I9: =SUMIF(Provstidata!$A:$A,$A9,Provstidata!$J:$J) | J9: =SUMIF(Provstidata!$A:$A,$A9,Provstidata!$K:$K) | K9: =SUMIF(Provstidata!$A:$A,$A9,Provstidata!$L:$L) | L9: =SUMIF(Provstidata!$A:$A,$A9,Provstidata!$M:$M) | M9: =SUMIF(Provstidata!$A:$A,$A9,Provstidata!$N:$N) | N9: =SUMIF(Provstidata!$A:$A,$A9,Provstidata!$O:$O) | O9: =SUMIF(Provstidata!$A:$A,$A9,Provstidata!$P:$P) | P9: =SUMIF(Provstidata!$A:$A,$A9,Provstidata!$R:$R) | Q9: =SUMIF(Provstidata!$A:$A,$A9,Provstidata!$S:$S) | R9: =SUMIF(Provstidata!$A:$A,$A9,Provstidata!$T:$T)
A10: Aalborg Stift | B10: =COUNTIF(Provstidata!$A:$A,$A10) | C10: =SUMIF(Provstidata!$A:$A,$A10,Provstidata!$C:$C) | D10: =SUMIF(Provstidata!$A:$A,$A10,Provstidata!$D:$D) | E10: =SUMIF(Provstidata!$A:$A,$A10,Provstidata!$E:$E) | F10: =IF(C10=0,"",D10/C10) | G10: =SUMIF(Provstidata!$A:$A,$A10,Provstidata!$G:$G) | H10: =SUMIF(Provstidata!$A:$A,$A10,Provstidata!$H:$H) | I10: =SUMIF(Provstidata!$A:$A,$A10,Provstidata!$J:$J) | J10: =SUMIF(Provstidata!$A:$A,$A10,Provstidata!$K:$K) | K10: =SUMIF(Provstidata!$A:$A,$A10,Provstidata!$L:$L) | L10: =SUMIF(Provstidata!$A:$A,$A10,Provstidata!$M:$M) | M10: =SUMIF(Provstidata!$A:$A,$A10,Provstidata!$N:$N) | N10: =SUMIF(Provstidata!$A:$A,$A10,Provstidata!$O:$O) | O10: =SUMIF(Provstidata!$A:$A,$A10,Provstidata!$P:$P) | P10: =SUMIF(Provstidata!$A:$A,$A10,Provstidata!$R:$R) | Q10: =SUMIF(Provstidata!$A:$A,$A10,Provstidata!$S:$S) | R10: =SUMIF(Provstidata!$A:$A,$A10,Provstidata!$T:$T)
A11: Aarhus Stift | B11: =COUNTIF(Provstidata!$A:$A,$A11) | C11: =SUMIF(Provstidata!$A:$A,$A11,Provstidata!$C:$C) | D11: =SUMIF(Provstidata!$A:$A,$A11,Provstidata!$D:$D) | E11: =SUMIF(Provstidata!$A:$A,$A11,Provstidata!$E:$E) | F11: =IF(C11=0,"",D11/C11) | G11: =SUMIF(Provstidata!$A:$A,$A11,Provstidata!$G:$G) | H11: =SUMIF(Provstidata!$A:$A,$A11,Provstidata!$H:$H) | I11: =SUMIF(Provstidata!$A:$A,$A11,Provstidata!$J:$J) | J11: =SUMIF(Provstidata!$A:$A,$A11,Provstidata!$K:$K) | K11: =SUMIF(Provstidata!$A:$A,$A11,Provstidata!$L:$L) | L11: =SUMIF(Provstidata!$A:$A,$A11,Provstidata!$M:$M) | M11: =SUMIF(Provstidata!$A:$A,$A11,Provstidata!$N:$N) | N11: =SUMIF(Provstidata!$A:$A,$A11,Provstidata!$O:$O) | O11: =SUMIF(Provstidata!$A:$A,$A11,Provstidata!$P:$P) | P11: =SUMIF(Provstidata!$A:$A,$A11,Provstidata!$R:$R) | Q11: =SUMIF(Provstidata!$A:$A,$A11,Provstidata!$S:$S) | R11: =SUMIF(Provstidata!$A:$A,$A11,Provstidata!$T:$T)
A12: I alt | B12: =SUM(B2:B11) | C12: =SUM(C2:C11) | D12: =SUM(D2:D11) | E12: =SUM(E2:E11) | F12: =D12/C12 | G12: =SUM(G2:G11) | H12: =SUM(H2:H11) | I12: =SUM(I2:I11) | J12: =SUM(J2:J11) | K12: =SUM(K2:K11) | L12: =SUM(L2:L11) | M12: =SUM(M2:M11) | N12: =SUM(N2:N11) | ... R12: =SUM(R2:R11)

Sheet Datakontrol
A1: Kontrolpunkt | B1: Resultat | C1: Bemærkning
A2: Provstier i ny tabel | B2: 102 | C2: Forventet 102
A3: Provstier i tidligere app-data | B3: 102 | C3: Forventet 102
A4: Gamle provstier uden match i ny tabel | B4: 0 | C4: Ingen
A5: Nye provstier uden match i gamle data | B5: 0 | C5: Ingen
A6: Primær kilde anvendt | B6: Ja | C6: Ny tabel anvendt for befolkning/medlemmer/økonomi/struktur/præster inkl. LOFI
A7: Supplerende provsti.dk-data bevaret | B7: Ja | C7: Sogne, sognepræster, overenskomstansatte og Præster i alt

Sheet Afvigelser
A1: Provsti | B1: Kolonne | C1: Tidligere app-data | D1: Ny master | E1: Forskel | F1: Bemærkning
A2: Assens Provsti | B2: Indbyggertal | C2: 40170 | D2: 40053 | E2: -117 | F2: Primær kilde i master er ny tabel, hvis feltet findes dér
A3: Assens Provsti | B3: Folkekirkemedlemmer | C3: 32650 | D3: 32527 | E3: -123 | F3: Primær kilde i master er ny tabel, hvis feltet findes dér
A4: Assens Provsti | B4: Medlemsprocent | C4: 0.813 | D4: 0.81209897 | E4: -0.00090103113 | F4: Primær kilde i master er ny tabel, hvis feltet findes dér
A5: Assens Provsti | B5: Menighedsråd | C5: 23 | D5: 22 | E5: -1 | F5: Primær kilde i master er ny tabel, hvis feltet findes dér
A6: Assens Provsti | B6: Kirker | D6: 31 | F6: Mangler i en af kilderne
A7: Assens Provsti | B7: Lokal ligning t.kr. | D7: 59205.43 | F7: Mangler i en af kilderne
A8: Assens Provsti | B8: Maks. stiftsbidrag 1 % (t.kr.) | D8: 592.0543 | F8: Mangler i en af kilderne
A9: Bogense Provsti | B9: Indbyggertal | C9: 29426 | D9: 29392 | E9: -34 | F9: Primær kilde i master er ny tabel, hvis feltet findes dér
A10: Bogense Provsti | B10: Folkekirkemedlemmer | C10: 24103 | D10: 24016 | E10: -87 | F10: Primær kilde i master er ny tabel, hvis feltet findes dér
A11: Bogense Provsti | B11: Medlemsprocent | C11: 0.819 | D11: 0.81709309 | E11: -0.0019069134 | F11: Primær kilde i master er ny tabel, hvis feltet findes dér
A12: Bogense Provsti | B12: Kirker | D12: 30 | F12: Mangler i en af kilderne
A13: Bogense Provsti | B13: Lokal ligning t.kr. | D13: 45762.202 | F13: Mangler i en af kilderne
A14: Bogense Provsti | B14: Maks. stiftsbidrag 1 % (t.kr.) | D14: 457.62202 | F14: Mangler i en af kilderne
A15: Fåborg Provsti | B15: Indbyggertal | C15: 21979 | D15: 21957 | E15: -22 | F15: Primær kilde i master er ny tabel, hvis feltet findes dér
A16: Fåborg Provsti | B16: Folkekirkemedlemmer | C16: 17558 | D16: 17515 | E16: -43 | F16: Primær kilde i master er ny tabel, hvis feltet findes dér
A17: Fåborg Provsti | B17: Medlemsprocent | C17: 0.799 | D17: 0.7976955 | E17: -0.0013045043 | F17: Primær kilde i master er ny tabel, hvis feltet findes dér
A18: Fåborg Provsti | B18: Kirker | D18: 20 | F18: Mangler i en af kilderne
A19: Fåborg Provsti | B19: Lokal ligning t.kr. | D19: 76840.259 | F19: Mangler i en af kilderne
A20: Fåborg Provsti | B20: Maks. stiftsbidrag 1 % (t.kr.) | D20: 768.40259 | F20: Mangler i en af kilderne
A21: Hjallese Provsti | B21: Indbyggertal | C21: 104443 | D21: 104714 | E21: 271 | F21: Primær kilde i master er ny tabel, hvis feltet findes dér
A22: Hjallese Provsti | B22: Folkekirkemedlemmer | C22: 79221 | D22: 79163 | E22: -58 | F22: Primær kilde i master er ny tabel, hvis feltet findes dér
A23: Hjallese Provsti | B23: Medlemsprocent | C23: 0.759 | D23: 0.75599251 | E23: -0.0030074871 | F23: Primær kilde i master er ny tabel, hvis feltet findes dér
A24: Hjallese Provsti | B24: Kirker | D24: 27 | F24: Mangler i en af kilderne
A25: Hjallese Provsti | B25: Maks. stiftsbidrag 1 % (t.kr.) | D25: 0 | F25: Mangler i en af kilderne
A26: Kerteminde-Nyborg Provsti | B26: Indbyggertal | C26: 56700 | D26: 56771 | E26: 71 | F26: Primær kilde i master er ny tabel, hvis feltet findes dér
A27: Kerteminde-Nyborg Provsti | B27: Folkekirkemedlemmer | C27: 44466 | D27: 44413 | E27: -53 | F27: Primær kilde i master er ny tabel, hvis feltet findes dér
A28: Kerteminde-Nyborg Provsti | B28: Medlemsprocent | C28: 0.784 | D28: 0.78231844 | E28: -0.0016815628 | F28: Primær kilde i master er ny tabel, hvis feltet findes dér
A29: Kerteminde-Nyborg Provsti | B29: Menighedsråd | C29: 19 | D29: 18 | E29: -1 | F29: Primær kilde i master er ny tabel, hvis feltet findes dér
A30: Kerteminde-Nyborg Provsti | B30: Kirker | D30: 39 | F30: Mangler i en af kilderne
A31: Kerteminde-Nyborg Provsti | B31: Lokal ligning t.kr. | D31: 81248.872 | F31: Mangler i en af kilderne
A32: Kerteminde-Nyborg Provsti | B32: Maks. stiftsbidrag 1 % (t.kr.) | D32: 812.48872 | F32: Mangler i en af kilderne
A33: Langeland-Ærø Provsti | B33: Indbyggertal | C33: 17607 | D33: 17556 | E33: -51 | F33: Primær kilde i master er ny tabel, hvis feltet findes dér
A34: Langeland-Ærø Provsti | B34: Folkekirkemedlemmer | C34: 13839 | D34: 13767 | E34: -72 | F34: Primær kilde i master er ny tabel, hvis feltet findes dér
A35: Langeland-Ærø Provsti | B35: Medlemsprocent | C35: 0.786 | D35: 0.78417635 | E35: -0.00182365 | F35: Primær kilde i master er ny tabel, hvis feltet findes dér
A36: Langeland-Ærø Provsti | B36: Kirker | D36: 30 | F36: Mangler i en af kilderne
A37: Langeland-Ærø Provsti | B37: Lokal ligning t.kr. | D37: 28842.8 | F37: Mangler i en af kilderne
A38: Langeland-Ærø Provsti | B38: Maks. stiftsbidrag 1 % (t.kr.) | D38: 288.428 | F38: Mangler i en af kilderne
A39: Middelfart Provsti | B39: Indbyggertal | C39: 40577 | D39: 40606 | E39: 29 | F39: Primær kilde i master er ny tabel, hvis feltet findes dér
A40: Middelfart Provsti | B40: Folkekirkemedlemmer | C40: 33142 | D40: 33146 | E40: 4 | F40: Primær kilde i master er ny tabel, hvis feltet findes dér
...

Sheet Kilder
A1: Felt/område | B1: Primær kilde | C1: Supplerende kilde | D1: Bemærkning
A2: Befolkning, medlemmer, ikke-medlemmer, medlemsprocent | B2: Kopi af Tabel vedr. stifter og provstier slut torsdag.xlsx / fanen Tabel | D2: Opgørelsen afviger marginalt fra tidligere app-data pga. opgørelsestidspunkt.
A3: Lokal ligning og maks. stiftsbidrag | B3: Kopi af Tabel vedr. stifter og provstier slut torsdag.xlsx / fanen Tabel | D3: Beløb er indlæst som t.kr. i masterfilen af hensyn til appens eksisterende format.
A4: Menighedsråd, pastorater, kirker | B4: Kopi af Tabel vedr. stifter og provstier slut torsdag.xlsx / fanen Tabel | D4: Kirker er angivet som kirker inkl. kapeller, også kommunale.
A5: Præster inkl. LOFI | B5: Kopi af Tabel vedr. stifter og provstier slut torsdag.xlsx / fanen Tabel | C5: Bilag 2 – Forslaget i tal | D5: LOFI = lokalt finansierede præstestillinger. Legacy-kolonnen "Præsteårsværk inkl. LOFI" er bevaret af hensyn til app-kompatibilitet, men bør senere omdøbes i appen.
A6: Sogne | B6: Tidligere app-datasæt baseret på provsti.dk-data | D6: Ikke i den nye tabel.
A7: Sognepræster | B7: Tidligere app-datasæt baseret på provsti.dk-data | D7: Ikke i den nye tabel.
A8: Overenskomstansatte sognepræster | B8: Tidligere app-datasæt baseret på provsti.dk-data | D8: Ikke i den nye tabel.
A9: Præster i alt | B9: Tidligere app-datasæt baseret på provsti.dk-data | D9: Sognepræster + overenskomstansatte sognepræster i tidligere data.
A10: Geografi | B10: data/provstier.geojson | D10: Uændret i v24.0.
A11: Formål med v24.0 | B11: Datakonsolidering | D11: Ingen funktionelle app-ændringer ud over at appens provstidata.xlsx nu er konsolideret.
