Workbook

Sheet Tabel
A1: Stift | B1: Provsti | C1: Medlemmer | D1: ikke medlem | E1: befolkning i alt | F1: Medlems-procent | G1: Lokal ligning | H1: Maks. Stiftsbidrag | I1: Antal Menighedsråd | J1: Antal Kirker inkl. Kapeller også kommunale | K1: Antal Pastorater | L1: Antal Præster | M1: Befolkningstilvækst (+/-) frem til 2040 tilknyttet kommune | N1: Befolkningstilvækst (+/-) frem til 2040 tilknyttet kommune i procent
A2: Fyens | B2: Assens Provsti | C2: 32527 | D2: 7526 | E2: =C2+D2 -> 40053 | F2: =C2/E2 -> 0.81209897 | G2: ='Lokal ligning'!F50 -> 59205430 | H2: =G2*1% -> 592054.3 | I2: 22 | J2: 31 | K2: 16 | L2: 18 | M2: =Befolkning!G51 -> -1345
A3: Fyens | B3: Bogense Provsti | C3: 24016 | D3: 5376 | E3: =C3+D3 -> 29392 | F3: =C3/E3 -> 0.81709309 | G3: ='Lokal ligning'!F56 -> 45762202 | H3: =G3*1% -> 457622.02 | I3: 18 | J3: 30 | K3: 11 | L3: 14 | M3: =Befolkning!G56 -> -902
A4: Fyens | B4: Fåborg Provsti | C4: 17515 | D4: 4442 | E4: =C4+D4 -> 21957 | F4: =C4/E4 -> 0.7976955 | G4: ='Lokal ligning'!F51 -> 76840259 | H4: =G4*1% -> 768402.59 | I4: 14 | J4: 20 | K4: 9 | L4: 10 | M4: =Befolkning!G52 -> 455
A5: Fyens | B5: Hjallese Provsti | C5: 79163 | D5: 25551 | E5: =C5+D5 -> 104714 | F5: =C5/E5 -> 0.75599251 | H5: =G5*1% -> 0 | I5: 20 | J5: 27 | K5: 17 | L5: 36
A6: Fyens | B6: Kerteminde-Nyborg Provsti | C6: 44413 | D6: 12358 | E6: =C6+D6 -> 56771 | F6: =C6/E6 -> 0.78231844 | G6: ='Lokal ligning'!F53+'Lokal ligning'!F52 -> 81248872 | H6: =G6*1% -> 812488.72 | I6: 18 | J6: 39 | K6: 18 | L6: 21 | M6: =Befolkning!G57+Befolkning!G53 -> -257
A7: Fyens | B7: Langeland-Ærø Provsti | C7: 13767 | D7: 3789 | E7: =C7+D7 -> 17556 | F7: =C7/E7 -> 0.78417635 | G7: ='Lokal ligning'!F57+'Lokal ligning'!F58 -> 28842800 | H7: =G7*1% -> 288428 | I7: 9 | J7: 30 | K7: 7 | L7: 11 | M7: =Befolkning!G60+Befolkning!G54 -> -1254
A8: Fyens | B8: Middelfart Provsti | C8: 33146 | D8: 7460 | E8: =C8+D8 -> 40606 | F8: =C8/E8 -> 0.81628331 | G8: ='Lokal ligning'!F49 -> 58156085 | H8: =G8*1% -> 581560.85 | I8: 13 | J8: 24 | K8: 10 | L8: 13 | M8: =Befolkning!G55 -> 2135
A9: Fyens | B9: Midtfyn Provsti | C9: 24467 | D9: 5849 | E9: =C9+D9 -> 30316 | F9: =C9/E9 -> 0.80706558 | H9: =G9*1% -> 0 | I9: 13 | J9: 23 | K9: 11 | L9: 8
A10: Fyens | B10: Odense Sankt Knuds Provsti | C10: 70051 | D10: 38666 | E10: =C10+D10 -> 108717 | F10: =C10/E10 -> 0.64434265 | G10: ='Lokal ligning'!F54 -> 1.7414786e+08 | H10: =G10*1% -> 1741478.6 | I10: 11 | J10: 17 | K10: 11 | L10: 26 | M10: =Befolkning!G58 -> 8432
A11: Fyens | B11: Svendborg Provsti | C11: 45484 | D11: 14580 | E11: =C11+D11 -> 60064 | F11: =C11/E11 -> 0.75725892 | G11: ='Lokal ligning'!F55 -> 84114012 | H11: =G11*1% -> 841140.12 | I11: 19 | J11: 34 | K11: 18 | L11: 20 | M11: =Befolkning!G59 -> 2727
A12: Fyens | C12: =SUM(C2:C11) -> 384549 | D12: =SUM(D2:D11) -> 125597 | E12: =SUM(E2:E11) -> 510146 | F12: =C12/E12 -> 0.75380185 | G12: =SUM(G2:G11) -> 6.0831752e+08 | H12: =G12*1% -> 6083175.2 | I12: =SUM(I2:I11) -> 157 | J12: =SUM(J2:J11) -> 275 | K12: =SUM(K2:K11) -> 128 | L12: =SUM(L2:L11)+1 -> 178 | M12: =SUM(M2:M11) -> 9991 | N12: =M12/E12 -> 0.01958459
A13: Haderslev | B13: Fredericia Provsti | C13: 39397 | D13: 13523 | E13: =C13+D13 -> 52920 | F13: =C13/E13 -> 0.74446334 | G13: ='Lokal ligning'!F68 -> 67414748 | H13: =G13*1% -> 674147.48 | I13: 10 | J13: 14 | K13: 10 | L13: 20 | M13: =Befolkning!G64 -> 1621
A14: Haderslev | B14: Haderslev Domprovsti | C14: 42941 | D14: 12187 | E14: =C14+D14 -> 55128 | F14: =C14/E14 -> 0.77893267 | G14: ='Lokal ligning'!F59 -> 77002240 | H14: =G14*1% -> 770022.4 | I14: 25 | J14: 32 | K14: 18 | L14: 27 | M14: =Befolkning!G65 -> -2353
A15: Haderslev | B15: Hedensted Provsti | C15: 38907 | D15: 9677 | E15: =C15+D15 -> 48584 | F15: =C15/E15 -> 0.8008192 | G15: ='Lokal ligning'!F87 -> 70743248 | H15: =G15*1% -> 707432.48 | I15: 20 | J15: 37 | K15: 16 | L15: 22 | M15: =Befolkning!G74 -> 3856
A16: Haderslev | B16: Kolding Provsti | C16: 71735 | D16: 24560 | E16: =C16+D16 -> 96295 | F16: =C16/E16 -> 0.74495041 | G16: ='Lokal ligning'!F70 -> 1.2701316e+08 | H16: =G16*1% -> 1270131.6 | I16: 24 | J16: 39 | K16: 22 | L16: 34 | M16: =Befolkning!G66 -> 3042
A17: Haderslev | B17: Sønderborg Provsti | C17: 54438 | D17: 19569 | E17: =C17+D17 -> 74007 | F17: =C17/E17 -> 0.73557907 | G17: ='Lokal ligning'!F61 -> 96872301 | H17: =G17*1% -> 968723.01 | I17: 23 | J17: 36 | K17: 20 | L17: 27 | M17: =Befolkning!G67 -> -3222
A18: Haderslev | B18: Vejle Provsti | C18: 76427 | D18: 29376 | E18: =C18+D18 -> 105803 | F18: =C18/E18 -> 0.72235192 | G18: ='Lokal ligning'!F71 -> 1.5793806e+08 | H18: =G18*1% -> 1579380.6 | I18: 24 | J18: 38 | K18: 23 | L18: 40 | M18: =Befolkning!G71 -> 9448
A19: Haderslev | B19: Aabenraa Provsti | C19: 42800 | D19: 15495 | E19: =C19+D19 -> 58295 | F19: =C19/E19 -> 0.73419676 | G19: ='Lokal ligning'!F67 -> 76710980 | H19: =G19*1% -> 767109.8 | I19: 19 | J19: 26 | K19: 16 | L19: 24 | M19: =Befolkning!G72 -> -2774
A20: Haderslev | C20: =SUM(C13:C19) -> 366645 | D20: =SUM(D13:D19) -> 124387 | E20: =SUM(E13:E19) -> 491032 | F20: =C20/E20 -> 0.7466825 | G20: =SUM(G13:G19) -> 6.7369473e+08 | H20: =G20*1% -> 6736947.3 | I20: =SUM(I13:I19) -> 145 | J20: =SUM(J13:J19) -> 222 | K20: =SUM(K13:K19) -> 125 | L20: =SUM(L13:L19)+9 -> 203 | M20: =SUM(M13:M19) -> 9618 | N20: =M20/E20 -> 0.019587318
A21: Helsingør | B21: Ballerup-Furesø Provsti | C21: 57614 | D21: 39272 | E21: =C21+D21 -> 96886 | F21: =C21/E21 -> 0.59465764 | G21: ='Lokal ligning'!F5+'Lokal ligning'!F20 -> 94940907 | H21: =G21*1% -> 949409.07 | I21: 7 | J21: 13 | K21: 6 | L21: 25 | M21: =Befolkning!G9+Befolkning!G25 -> 10383
A22: Helsingør | B22: Fredensborg Provsti | C22: 44535 | D22: 22914 | E22: =C22+D22 -> 67449 | F22: =C22/E22 -> 0.66027665 | G22: ='Lokal ligning'!F22+'Lokal ligning'!F25 -> 68792458 | H22: =G22*1% -> 687924.58 | I22: 6 | J22: 13 | K22: 6 | L22: 17 | M22: =Befolkning!G23+Befolkning!G30 -> 343
A23: Helsingør | B23: Frederikssund Provsti | C23: 68391 | D23: 25713 | E23: =C23+D23 -> 94104 | F23: =C23/E23 -> 0.72675976 | G23: ='Lokal ligning'!F27+'Lokal ligning'!F28 -> 1.2156687e+08 | H23: =G23*1% -> 1215668.7 | I23: 17 | J23: 28 | K23: 15 | L23: 32 | M23: =Befolkning!G22+Befolkning!G24 -> 5291
A24: Helsingør | B24: Frederiksværk Provsti | C24: 53698 | D24: 20012 | E24: =C24+D24 -> 73710 | F24: =C24/E24 -> 0.7285036 | G24: ='Lokal ligning'!F31+'Lokal ligning'!F34 -> 90257527 | H24: =G24*1% -> 902575.27 | I24: 16 | J24: 25 | K24: 13 | L24: 23 | M24: =Befolkning!G26+Befolkning!G27 -> 437
A25: Helsingør | B25: Gentofte Provsti | C25: 48605 | D25: 26481 | E25: =C25+D25 -> 75086 | F25: =C25/E25 -> 0.6473244 | G25: ='Lokal ligning'!F8 -> 62914377 | H25: =G25*1% -> 629143.77 | I25: 9 | J25: 14 | K25: 9 | L25: 19 | M25: =Befolkning!G11 -> -3466 | N25: =Befolkning!I11 -> -0.046275033
A26: Helsingør | B26: Gladsaxe-Herlev Provsti | C26: 55870 | D26: 47226 | E26: =C26+D26 -> 103096 | F26: =C26/E26 -> 0.54192209 | G26: ='Lokal ligning'!F9+'Lokal ligning'!F11 -> 94535170 | H26: =G26*1% -> 945351.7 | I26: 10 | J26: 14 | K26: 10 | L26: 28 | M26: =Befolkning!G12 -> 3981 | N26: =Befolkning!I12 -> 0.038890626
A27: Helsingør | B27: Glostrup Provsti | C27: 54408 | D27: 60552 | E27: =C27+D27 -> 114960 | F27: =C27/E27 -> 0.47327766 | G27: ='Lokal ligning'!F10+'Lokal ligning'!F12+'Lokal ligning'!F19+'Lokal ligning'!F6 -> 87883824 | H27: =G27*1% -> 878838.24 | I27: 9 | J27: 17 | K27: 9 | L27: 29 | M27: =Befolkning!G8 -> 10135 | N27: =Befolkning!I8 -> 0.08960621
A28: Helsingør | B28: Helsingør Domprovsti | C28: 43290 | D28: 21102 | E28: =C28+D28 -> 64392 | F28: =C28/E28 -> 0.67228848 | G28: ='Lokal ligning'!F23 -> 55124838 | H28: =G28*1% -> 551248.38 | I28: 10 | J28: 12 | K28: 9 | L28: 21 | M28: =Befolkning!G28 -> 1128 | N28: =Befolkning!I28 -> 0.017581047
A29: Helsingør | B29: Hillerød Provsti | C29: 56842 | D29: 25402 | E29: =C29+D29 -> 82244 | F29: =C29/E29 -> 0.69113856 | G29: ='Lokal ligning'!F21+'Lokal ligning'!F24 -> 79963177 | H29: =G29*1% -> 799631.77 | I29: 15 | J29: 25 | K29: 14 | L29: 27 | M29: =Befolkning!G29+Befolkning!G21 -> 4868
A30: Helsingør | B30: Høje Taastrup Provsti | C30: 37529 | D30: 48047 | E30: =C30+D30 -> 85576 | F30: =C30/E30 -> 0.43854585 | G30: ='Lokal ligning'!F14+'Lokal ligning'!F17 -> 63559280 | H30: =G30*1% -> 635592.8 | I30: 9 | J30: 11 | K30: 7 | L30: 18 | M30: =Befolkning!G16+Befolkning!G17 -> 10370
A31: Helsingør | B31: Kongens Lyngby Provsti | C31: 36601 | D31: 22321 | E31: =C31+D31 -> 58922 | F31: =C31/E31 -> 0.62117715 | G31: ='Lokal ligning'!F15 -> 63228431 | H31: =G31*1% -> 632284.31 | I31: 6 | J31: 10 | K31: 6 | L31: 18 | M31: =Befolkning!G18 -> 671
A32: Helsingør | B32: Rudersdal Provsti | C32: 39123 | D32: 18954 | E32: =C32+D32 -> 58077 | F32: =C32/E32 -> 0.67364017 | G32: ='Lokal ligning'!F26 -> 66611508 | H32: =G32*1% -> 666115.08 | I32: 8 | J32: 11 | K32: 8 | L32: 20 | M32: =Befolkning!G31 -> -1349
A33: Helsingør | B33: Rødovre-Hvidovre Provsti | C33: 56326 | D33: 42965 | E33: =C33+D33 -> 99291 | F33: =C33/E33 -> 0.56728203 | G33: ='Lokal ligning'!F16+'Lokal ligning'!F13 -> 80698250 | H33: =G33*1% -> 806982.5 | I33: 8 | J33: 14 | K33: 8 | L33: 25 | M33: =Befolkning!G15+Befolkning!G19 -> 5243
A34: Helsingør | C34: =SUM(C21:C33) -> 652832 | D34: =SUM(D21:D33) -> 420961 | E34: =SUM(E21:E33) -> 1073793 | F34: =C34/E34 -> 0.6079682 | G34: =SUM(G21:G33) -> 1.0300766e+09 | H34: =G34*1% -> 10300766 | I34: =SUM(I21:I33) -> 130 | J34: =SUM(J21:J33) -> 207 | K34: =SUM(K21:K33) -> 120 | L34: =SUM(L21:L33) -> 302 | M34: =SUM(M21:M33) -> 48035 | N34: =M34/E34 -> 0.044733948
A35: København | B35: Amagerbro Provsti | C35: 82209 | D35: 87908 | E35: =C35+D35 -> 170117 | F35: =C35/E35 -> 0.48324976 | H35: =G35*1% -> 0 | I35: =GETPIVOTDATA("MRKode",Menighedsråd!$A$1,"Stift","Københavns Stift","Provsti","Amagerbro Provsti") -> 12 | J35: 16 | K35: 10 | L35: 33
A36: København | B36: Amagerland Provsti | C36: 40442 | D36: 18256 | E36: =C36+D36 -> 58698 | F36: =C36/E36 -> 0.68898429 | G36: ='Lokal ligning'!F18+'Lokal ligning'!F7 -> 48688610 | H36: =G36*1% -> 486886.1 | I36: =GETPIVOTDATA("MRKode",Menighedsråd!$A$1,"Stift","Københavns Stift","Provsti","Amagerland Provsti") -> 6 | J36: 9 | K36: 6 | L36: 18 | M36: =Befolkning!G6 -> 197 | N36: =Befolkning!I6 -> 0.0033579355
A37: København | B37: Bispebjerg-Brønshøj Provsti | C37: 40597 | D37: 55843 | E37: =C37+D37 -> 96440 | F37: =C37/E37 -> 0.42095603 | H37: =G37*1% -> 0 | I37: =GETPIVOTDATA("MRKode",Menighedsråd!$A$1,"Stift","Københavns Stift","Provsti","Bispebjerg-Brønshøj Provsti") -> 10 | J37: 14 | K37: 9 | L37: 25
A38: København | B38: Bornholms Provsti | C38: 29081 | D38: 9622 | E38: =C38+D38 -> 38703 | F38: =C38/E38 -> 0.75138878 | G38: ='Lokal ligning'!F48 -> 49111137 | H38: =G38*1% -> 491111.37 | I38: =GETPIVOTDATA("MRKode",Menighedsråd!$A$1,"Stift","Københavns Stift","Provsti","Bornholms Provsti") -> 18 | J38: 29 | K38: 14 | L38: 18 | M38: =Befolkning!G32 -> -3143 | N38: =Befolkning!I32 -> -0.081007242
A39: København | B39: Frederiksberg Provsti | C39: 61301 | D39: 45132 | E39: =C39+D39 -> 106433 | F39: =C39/E39 -> 0.57595858 | G39: ='Lokal ligning'!F4 -> 70094214 | H39: =G39*1% -> 700942.14 | I39: =GETPIVOTDATA("MRKode",Menighedsråd!$A$1,"Stift","Københavns Stift","Provsti","Frederiksberg Provsti") -> 9 | J39: 18 | K39: 9 | L39: 28 | M39: =Befolkning!G5 -> -3801 | N39: =Befolkning!I5 -> -0.035889301
A40: København | B40: Holmens og Østerbro Provsti | C40: 61354 | D40: 51496 | E40: =C40+D40 -> 112850 | F40: =C40/E40 -> 0.54367745 | H40: =G40*1% -> 0 | I40: =GETPIVOTDATA("MRKode",Menighedsråd!$A$1,"Stift","Københavns Stift","Provsti","Holmens og Østerbro Provsti") -> 14 | J40: 20 | K40: 13 | L40: 28
...

Sheet Befolkning
B1: Befolkningsfremskrivning 2025 efter kommune og tid
B2: Enhed: Antal
A3: Provsti | B3: Kommune | C3: 2026 | D3: 2041 | G3: Vækst (+/-) | I3: Procentvis ændring
A4: Amagerbro/Bispebjerg-Brønshøj/Holmens-Østerbro/Nørrebro/Vor Frue Vesterbro | B4: København | C4: 672684 | D4: 701953 | G4: =D4-C4 -> 29269 | I4: =G4/C4 -> 0.043510772
A5: Frederiksberg | B5: Frederiksberg | C5: 105909 | D5: 102108 | G5: =D5-C5 -> -3801 | I5: =G5/C5 -> -0.035889301
A6: Amagerland provsti | B6: Dragør | C6: 14377 | D6: 13286 | E6: =C6+C7 -> 58667 | F6: =D6+D7 -> 58864 | G6: =F6-E6 -> 197 | I6: =G6/E6 -> 0.0033579355
A7: Amagerland provsti | B7: Tårnby | C7: 44290 | D7: 45578 | G7: =D7-C7 -> 1288
A8: Glostrup | B8: Albertslund | C8: 28207 | D8: 28466 | E8: =C8+C10+C13+C20 -> 113106 | F8: =D8+D10+D13+D20 -> 123241 | G8: =F8-E8 -> 10135 | I8: =G8/E8 -> 0.08960621
A9: Ballerup-Furesø | B9: Ballerup | C9: 53602 | D9: 60005 | E9: =C9+C25 -> 96413 | F9: =D9+D25 -> 104806 | G9: =F9-E9 -> 8393 | I9: =G9/E9 -> 0.087052576
A10: Glostrup | B10: Brøndby | C10: 41311 | D10: 48759 | G10: =D10-C10 -> 7448 | I10: =G10/C10 -> 0.18029096
A11: Gentofte | B11: Gentofte | C11: 74900 | D11: 71434 | G11: =D11-C11 -> -3466 | I11: =G11/C11 -> -0.046275033
A12: Gladsaxe-Herlev | B12: Gladsaxe | C12: 71257 | D12: 72598 | E12: =C12+C14 -> 102364 | F12: =D12+D14 -> 106345 | G12: =F12-E12 -> 3981 | I12: =G12/E12 -> 0.038890626
A13: Glostrup | B13: Glostrup | C13: 25068 | D13: 26339 | G13: =D13-C13 -> 1271 | I13: =G13/C13 -> 0.05070209
A14: Gladsaxe-Herlev | B14: Herlev | C14: 31107 | D14: 33747 | G14: =D14-C14 -> 2640 | I14: =G14/C14 -> 0.084868358
A15: Rødovre-Hvidovre | B15: Hvidovre | C15: 53895 | D15: 53999 | G15: =D15-C15 -> 104 | I15: =G15/C15 -> 0.0019296781
A16: Høje-Taastrup | B16: Høje-Taastrup | C16: 60271 | D16: 69723 | G16: =D16-C16 -> 9452 | I16: =G16/C16 -> 0.15682501
A17: Høje-Taastrup | B17: Ishøj | C17: 24552 | D17: 25470 | G17: =D17-C17 -> 918 | I17: =G17/C17 -> 0.037390029
A18: Kgs. Lyngby | B18: Lyngby-Taarbæk | C18: 58995 | D18: 59666 | G18: =D18-C18 -> 671 | I18: =G18/C18 -> 0.011373845
A19: Rødovre-Hvidovre | B19: Rødovre | C19: 45403 | D19: 50542 | G19: =D19-C19 -> 5139 | I19: =G19/C19 -> 0.11318635
A20: Glostrup | B20: Vallensbæk | C20: 18520 | D20: 19677 | G20: =D20-C20 -> 1157 | I20: =G20/C20 -> 0.062473002
A21: Hillerød | B21: Allerød | C21: 26101 | D21: 25534 | G21: =D21-C21 -> -567 | I21: =G21/C21 -> -0.021723306
A22: Frederikssund | B22: Egedal | C22: 45903 | D22: 48709 | G22: =D22-C22 -> 2806 | I22: =G22/C22 -> 0.061128902
A23: Fredensborg | B23: Fredensborg | C23: 42396 | D23: 43425 | G23: =D23-C23 -> 1029 | I23: =G23/C23 -> 0.024271158
A24: Frederikssund | B24: Frederikssund | C24: 47367 | D24: 49852 | G24: =D24-C24 -> 2485 | I24: =G24/C24 -> 0.052462685
... A32: Bornholm | B32: Bornholm | C32: 38799 | D32: 35656 | G32: =D32-C32 -> -3143 | I32: =G32/C32 -> -0.081007242
B33: Christiansø | C33: 0 | D33: 0 | G33: =D33-C33 -> 0
A34: Greve-Solrød | B34: Greve | C34: 54037 | D34: 57803 | G34: =D34-C34 -> 3766 | I34: =G34/C34 -> 0.069692988
A35: Køge | B35: Køge | C35: 63684 | D35: 65671 | G35: =D35-C35 -> 1987 | I35: =G35/C35 -> 0.03120093
A36: Lejre | B36: Lejre | C36: 29850 | D36: 31705 | G36: =D36-C36 -> 1855 | I36: =G36/C36 -> 0.062144054
A37: Roskilde | B37: Roskilde | C37: 92142 | D37: 95201 | G37: =D37-C37 -> 3059 | I37: =G37/C37 -> 0.033198758
A38: Greve-Solrød | B38: Solrød | C38: 24960 | D38: 26629 | G38: =D38-C38 -> 1669 | I38: =G38/C38 -> 0.066866987
A39: Tryggevælde | B39: Faxe | C39: 37989 | D39: 38684 | G39: =D39-C39 -> 695 | I39: =G39/C39 -> 0.01829477
A40: Lolland Østre/Lolland Falster | B40: Guldborgsund | C40: 59187 | D40: 55748 | G40: =D40-C40 -> -3439 | I40: =G40/C40 -> -0.058103976
A41: Holbæk | B41: Holbæk | C41: 74960 | D41: 77965 | G41: =D41-C41 -> 3005 | I41: =G41/C41 -> 0.040088047
A42: Kalundborg | B42: Kalundborg | C42: 47965 | D42: 45459 | G42: =D42-C42 -> -2506 | I42: =G42/C42 -> -0.05224643
A43: Lolland Vestre/Maribo | B43: Lolland | C43: 38845 | D43: 34978 | G43: =D43-C43 -> -3867 | I43: =G43/C43 -> -0.099549492
A44: Næstved | B44: Næstved | C44: 85189 | D44: 86157 | G44: =D44-C44 -> 968 | I44: =G44/C44 -> 0.011362969
A45: Odsherred | B45: Odsherred | C45: 32077 | D45: 29595 | G45: =D45-C45 -> -2482 | I45: =G45/C45 -> -0.077376313
... A102: Aalborg Budolfi/Aalborg Nordre/Aalborg Østre/Aalborg Vestre | B102: Aalborg | C102: 225942 | D102: 236360 | G102: =D102-C102 -> 10418 | I102: =G102/C102 -> 0.046109178
B104: På grund af afrundinger vil summering af alle aldre i tabellen afvige fra hele kommunens folketal. | G104: =SUM(G4:G102) -> 170798

Sheet Folkekirkemedlemmer mv
A1: Befolkningen den 1. i kvartalet efter tid, provsti og folkekirkemedlemskab
A2: Enhed: Antal | E2: Medlemsprocent
C3: Medlem af Folkekirken | D3: Ikke medlem af Folkekirken
A4: 2026K2 | B4: 1-01 Københavns Vor Frue Provsti | C4: 0 | D4: 0
B5: 1-02 Københavns Holmens Provsti | C5: 0 | D5: 0
B6: 1-03 Østerbro Provsti | C6: 0 | D6: 0
B7: 1-04 Nørrebro Provsti | C7: 35310 | D7: 41146 | E7: =C7/(C7+D7) -> 0.46183426
B8: 1-05 Vesterbro Provsti | C8: 0 | D8: 0
B9: 1-06 Frederiksberg Provsti | C9: 61301 | D9: 45132 | E9: =C9/(C9+D9) -> 0.57595858
B10: 1-07 Bornholms Provsti | C10: 29081 | D10: 9622 | E10: =C10/(C10+D10) -> 0.75138878
B11: 1-10 Bispebjerg-Brønshøj Provsti | C11: 40597 | D11: 55843 | E11: =C11/(C11+D11) -> 0.42095603
B12: 1-11 Valby-Vanløse Provsti | C12: 56847 | D12: 51901 | E12: =C12/(C12+D12) -> 0.52274065
B13: 1-12 Amagerbro Provsti | C13: 82209 | D13: 87908 | E13: =C13/(C13+D13) -> 0.48324976
B14: 1-13 Amagerland Provsti | C14: 40442 | D14: 18256 | E14: =C14/(C14+D14) -> 0.68898429
B15: 1-14 Vor Frue-Vesterbro Provsti | C15: 51772 | D15: 57055 | E15: =C15/(C15+D15) -> 0.47572753
B16: 1-15 Holmens og Østerbro Provsti | C16: 61354 | D16: 51496 | E16: =C16/(C16+D16) -> 0.54367745
C17: =SUM(C4:C16) -> 458913 | D17: =SUM(D4:D16) -> 418359 | E17: =C17/(C17+D17) -> 0.5231137
B18: 2-03 Gladsaxe-Herlev Provsti | C18: 55870 | D18: 47226 | E18: =C18/(C18+D18) -> 0.54192209
B19: 2-04 Gentofte Provsti | C19: 48605 | D19: 26481 | E19: =C19/(C19+D19) -> 0.6473244
B20: 2-05 Glostrup Provsti | C20: 54408 | D20: 60552 | E20: =C20/(C20+D20) -> 0.47327766
B21: 2-06 Helsingør Domprovsti | C21: 43290 | D21: 21102 | E21: =C21/(C21+D21) -> 0.67228848
B22: 2-07 Fredensborg Provsti | C22: 44535 | D22: 22914 | E22: =C22/(C22+D22) -> 0.66027665
B23: 2-08 Frederikssund Provsti | C23: 68391 | D23: 25713 | E23: =C23/(C23+D23) -> 0.72675976
B24: 2-09 Frederiksværk Provsti | C24: 53698 | D24: 20012 | E24: =C24/(C24+D24) -> 0.7285036
B25: 2-10 Rødovre-Hvidovre Provsti | C25: 56326 | D25: 42965 | E25: =C25/(C25+D25) -> 0.56728203
B26: 2-11 Ballerup-Furesø Provsti | C26: 57614 | D26: 39272 | E26: =C26/(C26+D26) -> 0.59465764
B27: 2-12 Kongens Lyngby Provsti | C27: 36601 | D27: 22321 | E27: =C27/(C27+D27) -> 0.62117715
B28: 2-13 Hillerød Provsti | C28: 56842 | D28: 25402 | E28: =C28/(C28+D28) -> 0.69113856
B29: 2-14 Høje Taastrup Provsti | C29: 37529 | D29: 48047 | E29: =C29/(C29+D29) -> 0.43854585
B30: 2-15 Rudersdal Provsti | C30: 39123 | D30: 18954 | E30: =C30/(C30+D30) -> 0.67364017
C31: =SUM(C18:C30) -> 652832 | D31: =SUM(D18:D30) -> 420961 | E31: =C31/(C31+D31) -> 0.6079682
B32: 3-01 Roskilde Domprovsti | C32: 65635 | D32: 27430 | E32: =C32/(C32+D32) -> 0.70525976
B33: 3-02 Lejre Provsti | C33: 21267 | D33: 8671 | E33: =C33/(C33+D33) -> 0.71036809
B34: 3-03 Køge Provsti | C34: 45332 | D34: 18716 | E34: =C34/(C34+D34) -> 0.70778166
B35: 3-04 Kalundborg Provsti | C35: 37125 | D35: 10717 | E35: =C35/(C35+D35) -> 0.77599181
B36: 3-05 Holbæk Provsti | C36: 55936 | D36: 19193 | E36: =C36/(C36+D36) -> 0.74453274
B37: 3-06 Odsherred Provsti | C37: 25048 | D37: 6886 | E37: =C37/(C37+D37) -> 0.78436776
B38: 3-07 Ringsted-Sorø Provsti | C38: 48894 | D38: 18061 | E38: =C38/(C38+D38) -> 0.73025166
B39: 3-08 Slagelse Provsti | C39: 60360 | D39: 20473 | E39: =C39/(C39+D39) -> 0.74672473
B40: 3-09 Skælskør Provsti | C40: 0 | D40: 0
...

Sheet Lokal ligning
A1: 2026
A2: KOM | B2: KOMNR | C2: Forskudsbeløb | D2: Landskirkeskat 2026 (kr.) | F2: Lokal ligning ekskl. Landskirkeskat
A3: København | B3: 101 | C3: 723225 | D3: 1.3167435e+08 | F3: =(C3*1000)-D3 -> 5.9155065e+08
A4: Frederiksberg | B4: 147 | C4: 98906 | D4: 28811786 | F4: =(C4*1000)-D4 -> 70094214
A5: Ballerup | B5: 151 | C5: 58188 | D5: 11300299 | F5: =(C5*1000)-D5 -> 46887701
A6: Brøndby | B6: 153 | C6: 33879 | D6: 6168111.4 | F6: =(C6*1000)-D6 -> 27710889
A7: Dragør | B7: 155 | C7: 19989 | D7: 4772970.7 | F7: =(C7*1000)-D7 -> 15216029
A8: Gentofte | B8: 157 | C8: 102017 | D8: 39102623 | F8: =(C8*1000)-D8 -> 62914377
A9: Gladsaxe | B9: 159 | C9: 80065 | D9: 15548969 | F9: =(C9*1000)-D9 -> 64516031
A10: Glostrup | B10: 161 | C10: 28640 | D10: 5214436 | F10: =(C10*1000)-D10 -> 23425564
A11: Herlev | B11: 163 | C11: 36234 | D11: 6214861.4 | F11: =(C11*1000)-D11 -> 30019139
A12: Albertslund | B12: 165 | C12: 25163 | D12: 4581350.4 | F12: =(C12*1000)-D12 -> 20581650
A13: Hvidovre | B13: 167 | C13: 56598 | D13: 11449411 | F13: =(C13*1000)-D13 -> 45148589
A14: Høje-Taastrup | B14: 169 | C14: 56827 | D14: 10346222 | F14: =(C14*1000)-D14 -> 46480778
... A100: Hjørring | B100: 860 | C100: 130322 | D100: 15950977 | F100: =(C100*1000)-D100 -> 1.1437102e+08
D101: 1.4765113e+09 | F101: =SUM(F3:F100) -> 7.3257877e+09

Sheet Præster
A1: Stift/Provsti | B1: Antal Præster
A2: Fyens Stift
A3: (tom) | B3: 1
A4: Assens Provsti | B4: 18
A5: Bogense Provsti | B5: 14
A6: Fåborg Provsti | B6: 10
A7: Hjallese Provsti | B7: 36
A8: Kerteminde-Nyborg Provsti | B8: 21
A9: Langeland-Ærø Provsti | B9: 11
A10: Middelfart Provsti | B10: 13
A11: Midtfyn Provsti | B11: 8
A12: Odense Sankt Knuds Provsti | B12: 26
A13: Svendborg Provsti | B13: 20
A15: Haderslev Stift
A16: (tom) | B16: 9
A17: Fredericia Provsti | B17: 20
A18: Haderslev Domprovsti | B18: 27
A19: Hedensted Provsti | B19: 22
A20: Kolding Provsti | B20: 34
A21: Sønderborg Provsti | B21: 27
A22: Vejle Provsti | B22: 40
A23: Aabenraa Provsti | B23: 24
A24: Helsingør Stift
A25: Ballerup-Furesø Provsti | B25: 25
A26: Fredensborg Provsti | B26: 17
A27: Frederikssund Provsti | B27: 32
A28: Frederiksværk Provsti | B28: 23
A29: Gentofte Provsti | B29: 19
A30: Gladsaxe-Herlev Provsti | B30: 28
A31: Glostrup Provsti | B31: 29
A32: Helsingør Domprovsti | B32: 21
A33: Hillerød Provsti | B33: 27
A34: Høje Taastrup Provsti | B34: 18
A35: Kongens Lyngby Provsti | B35: 18
A36: Rudersdal Provsti | B36: 20
A37: Rødovre-Hvidovre Provsti | B37: 25
A38: Københavns Stift
A39: (tom) | B39: 1
A40: Amagerbro Provsti | B40: 33
A41: Amagerland Provsti | B41: 18
...

Sheet Pastorater
A1: Stift/Provsti | B1: Antal Pastorater
A2: Fyens Stift | B2: 128
A3: Assens Provsti | B3: 16
A4: Bogense Provsti | B4: 11
A5: Fåborg Provsti | B5: 9
A6: Hjallese Provsti | B6: 17
A7: Kerteminde-Nyborg Provsti | B7: 18
A8: Langeland-Ærø Provsti | B8: 7
A9: Middelfart Provsti | B9: 10
A10: Midtfyn Provsti | B10: 11
A11: Odense Sankt Knuds Provsti | B11: 11
A12: Svendborg Provsti | B12: 18
A13: Haderslev Stift | B13: 125
... A113: Aarhus Vestre Provsti | B113: 10
A114: (tom)
A115: (tom)
A116: Hovedtotal | B116: 1145

Sheet Menighedsråd
A1: Stift/Provsti | B1: Antal menighedsråd
A2: Fyens Stift | B2: 157
A3: Assens Provsti | B3: 22
A4: Bogense Provsti | B4: 18
A5: Fåborg Provsti | B5: 14
A6: Hjallese Provsti | B6: 20
A7: Kerteminde-Nyborg Provsti | B7: 18
A8: Langeland-Ærø Provsti | B8: 9
A9: Middelfart Provsti | B9: 13
A10: Midtfyn Provsti | B10: 13
A11: Odense Sankt Knuds Provsti | B11: 11
A12: Svendborg Provsti | B12: 19
A13: Haderslev Stift | B13: 145
... A114: Hovedtotal | B114: 1545

Sheet Detalje1
A1: Detaljer for Antal Kirker - Provsti: Hillerød Provsti, Stift: Helsingør Stift
A3: Stift | B3: Provsti | C3: Sognekode | D3: Sogn | E3: Navn | F3: Kirketype
A4: Helsingør Stift | B4: Hillerød Provsti | C4: 9241 | D4: Gadevang Sogn | E4: Gadevang Kirke | F4: Kirke
A5: Helsingør Stift | B5: Hillerød Provsti | C5: 9155 | D5: Engholm Sogn | E5: Engholmkirken | F5: Kirke
A6: Helsingør Stift | B6: Hillerød Provsti | C6: 9154 | D6: Grønnevang Sogn | E6: Grønnevang Kirke | F6: Kirke
A7: Helsingør Stift | B7: Hillerød Provsti | C7: 7467 | D7: Ullerød Sogn | E7: Ullerød Kirke | F7: Kirke
A8: Helsingør Stift | B8: Hillerød Provsti | C8: 7450 | D8: Lillerød Sogn | E8: Lillerød Kirke | F8: Kirke
A9: Helsingør Stift | B9: Hillerød Provsti | C9: 7449 | D9: Blovstrød Sogn | E9: Blovstrød Kirke | F9: Kirke
A10: Helsingør Stift | B10: Hillerød Provsti | C10: 7436 | D10: Frederiksborg Slotssogn | E10: Nyhuse Kapel | F10: Kirke
A11: Helsingør Stift | B11: Hillerød Provsti | C11: 7436 | D11: Frederiksborg Slotssogn | E11: Frederiksborg Slotskirke | F11: Kirke
A12: Helsingør Stift | B12: Hillerød Provsti | C12: 7429 | D12: Nødebo Sogn | E12: Nødebo Kirke | F12: Kirke
A13: Helsingør Stift | B13: Hillerød Provsti | C13: 7426 | D13: Uggeløse Sogn | E13: Uggeløse Kirke | F13: Kirke
A14: Helsingør Stift | B14: Hillerød Provsti | C14: 7425 | D14: Lynge Sogn | E14: Lynge Kirke | F14: Kirke
... A28: Helsingør Stift | B28: Hillerød Provsti | C28: 7401 | D28: Tjæreby Sogn | E28: Tjæreby Kirke | F28: Kirke

Sheet Kirker
A1: Stift/Provsti | B1: Antal Kirker
A2: Fyens Stift | B2: 275
A3: Assens Provsti | B3: 31
A4: Bogense Provsti | B4: 30
A5: Fåborg Provsti | B5: 20
A6: Hjallese Provsti | B6: 27
A7: Kerteminde-Nyborg Provsti | B7: 39
A8: Langeland-Ærø Provsti | B8: 30
A9: Middelfart Provsti | B9: 24
A10: Midtfyn Provsti | B10: 23
A11: Odense Sankt Knuds Provsti | B11: 17
A12: Svendborg Provsti | B12: 34
A13: Haderslev Stift | B13: 222
... A113: Aarhus Vestre Provsti | B113: 21
A114: (tom)
A115: (tom)
A116: Hovedtotal | B116: 2657

Sheet Kirker fordelt efter art
A1: Antal af Navn | B1: Kolonnemærkater
A2: Rækkemærkater | B2: Filialkirke | C2: Fængselskirke | D2: Kirke | E2: Kirkesal | F2: (tom) | G2: Hovedtotal
A3: Fyens Stift | B3: 8 | C3: 2 | D3: 255 | E3: 10 | G3: 275
A4: Assens Provsti | D4: 30 | E4: 1 | G4: 31
A5: Bogense Provsti | B5: 3 | D5: 27 | G5: 30
A6: Fåborg Provsti | B6: 1 | D6: 19 | G6: 20
A7: Hjallese Provsti | D7: 26 | E7: 1 | G7: 27
A8: Kerteminde-Nyborg Provsti | C8: 1 | D8: 35 | E8: 3 | G8: 39
A9: Langeland-Ærø Provsti | B9: 3 | D9: 27 | G9: 30
A10: Middelfart Provsti | D10: 22 | E10: 2 | G10: 24
A11: Midtfyn Provsti | C11: 1 | D11: 20 | E11: 2 | G11: 23
A12: Odense Sankt Knuds Provsti | D12: 16 | E12: 1 | G12: 17
A13: Svendborg Provsti | B13: 1 | D13: 33 | G13: 34
A14: Haderslev Stift | B14: 9 | C14: 1 | D14: 210 | E14: 2 | G14: 222
A15: Fredericia Provsti | D15: 14 | G15: 14
A16: Haderslev Domprovsti | B16: 2 | D16: 30 | G16: 32
A17: Hedensted Provsti | C17: 1 | D17: 36 | G17: 37
A18: Kolding Provsti | B18: 1 | D18: 38 | G18: 39
A19: Sønderborg Provsti | B19: 1 | D19: 35 | G19: 36
A20: Vejle Provsti | B20: 2 | D20: 34 | E20: 2 | G20: 38
A21: Aabenraa Provsti | B21: 3 | D21: 23 | G21: 26
A22: Helsingør Stift | B22: 13 | C22: 2 | D22: 189 | E22: 3 | G22: 207
A23: Ballerup-Furesø Provsti | B23: 4 | D23: 9 | G23: 13
A24: Fredensborg Provsti | B24: 3 | D24: 10 | G24: 13
A25: Frederikssund Provsti | B25: 1 | D25: 27 | G25: 28
A26: Frederiksværk Provsti | B26: 2 | D26: 23 | G26: 25
A27: Gentofte Provsti | D27: 13 | E27: 1 | G27: 14
A28: Gladsaxe-Herlev Provsti | D28: 14 | G28: 14
A29: Glostrup Provsti | C29: 2 | D29: 15 | G29: 17
A30: Helsingør Domprovsti | B30: 1 | D30: 11 | G30: 12
A31: Hillerød Provsti | D31: 25 | G31: 25
A32: Høje Taastrup Provsti | B32: 1 | D32: 10 | G32: 11
A33: Kongens Lyngby Provsti | D33: 10 | G33: 10
A34: Rudersdal Provsti | D34: 11 | G34: 11
A35: Rødovre-Hvidovre Provsti | B35: 1 | D35: 11 | E35: 2 | G35: 14
A36: Københavns Stift | B36: 7 | D36: 138 | E36: 5 | G36: 150
A37: Amagerbro Provsti | D37: 16 | G37: 16
A38: Amagerland Provsti | D38: 9 | G38: 9
A39: Bispebjerg-Brønshøj Provsti | D39: 14 | G39: 14
A40: Bornholms Provsti | B40: 2 | D40: 26 | E40: 1 | G40: 29
...

Sheet Graf befolkning
A2: Fyen | B2: =Tabel!M12 -> 9991
A3: Haderslev | B3: =Tabel!M20 -> 9618
A4: Helsingør | B4: =Tabel!M34 -> 48035
A5: København | B5: =Tabel!M44 -> 22522
A6: Lolland Falster | B6: =Tabel!M49 -> -7306
A7: Ribe | B7: =Tabel!M58 -> -13195
A8: Roskilde | B8: =Tabel!M71 -> 13148
A9: Viborg | B9: =Tabel!M83 -> -14373
A10: Aalborg | B10: =Tabel!M98 -> -4391
A11: Aarhus | B11: =Tabel!M113 -> 92945
B13: =SUM(B2:B12) -> 156994
